Workbook

Sheet IS
A1: Particulars | B1: 2024 | C1: =B1+1 -> 2025 | D1: =C1+1 -> 2026 | E1: =D1+1 -> 2027 | F1: =E1+1 -> 2028 | G1: =F1+1 -> 2029 | H1: =G1+1 -> 2030
A2: Revenue from Operations | B2: 61896 | C2: 63121 | D2: =Assumption!D2 -> 65571.748 | E2: =Assumption!E2 -> 70443.375 | F2: =Assumption!F2 -> 76199.837 | G2: =Assumption!G2 -> 82987.518 | H2: =Assumption!H2 -> 90986.274
A3: Other Income | B3: 811 | C3: 1017 | D3: =Assumption!D3 -> 1118.7 | E3: =Assumption!E3 -> 1241.757 | F3: =Assumption!F3 -> 1390.7678 | G3: =Assumption!G3 -> 1571.5677 | H3: =Assumption!H3 -> 1791.5871
A4: Total Income | B4: =SUM(B2:B3) -> 62707 | C4: =SUM(C2:C3) -> 64138 | D4: =SUM(D2:D3) -> 66690.448 | E4: =SUM(E2:E3) -> 71685.132 | F4: =SUM(F2:F3) -> 77590.605 | G4: =SUM(G2:G3) -> 84559.085 | H4: =SUM(H2:H3) -> 92777.861
A5: Cost of Materials Consumed | B5: 19257 | C5: 19458 | D5: =Assumption!D30 -> 20307.037 | E5: =Assumption!E30 -> 21765.486 | F5: =Assumption!F30 -> 23571.289 | G5: =Assumption!G30 -> 25656.157 | H5: =Assumption!H30 -> 28137.141
A6: Purchases of Stock-in-trade | B6: 10514 | C6: 11272 | D6: =Assumption!D33 -> 11424.016 | E6: =Assumption!E33 -> 12426.186 | F6: =Assumption!F33 -> 13358.641 | G6: =Assumption!G33 -> 14593.781 | H6: =Assumption!H33 -> 15975.632
A7: Changes in inventories of FG and WIP | B7: -11 | C7: -153 | D7: =Assumption!D6 -> 0 | E7: =Assumption!E6 -> 0 | F7: =Assumption!F6 -> 0 | G7: =Assumption!G6 -> 0 | H7: =Assumption!H6 -> 0
A8: Employee benefits expenses | B8: 3009 | C8: 3077 | D8: =Assumption!D7 -> 3457.3172 | E8: =Assumption!E7 -> 3939.7858 | F8: =Assumption!F7 -> 4552.8165 | G8: =Assumption!G7 -> 5334.7627 | H8: =Assumption!H7 -> 6337.6981
A9: Finance Costs | B9: 334 | C9: 395 | D9: ='Debt Schedule'!D16 -> 394.57051 | E9: ='Debt Schedule'!E16 -> 398.29975 | F9: ='Debt Schedule'!F16 -> 402.02899 | G9: ='Debt Schedule'!G16 -> 405.75824 | H9: ='Debt Schedule'!H16 -> 409.48748
A10: Depreciation and amortisation expenses | B10: 1216 | C10: 1355 | D10: ='CAPEX Schedule '!D22 -> 1413.0518 | E10: ='CAPEX Schedule '!E22 -> 1472.9202 | F10: ='CAPEX Schedule '!F22 -> 1534.6623 | G10: ='CAPEX Schedule '!G22 -> 1598.3365 | H10: ='CAPEX Schedule '!H22 -> 1664.0034
A11: Other Expenses | B11: 14464 | C11: 14615 | D11: =Assumption!D42 -> 15018.446 | E11: =Assumption!E42 -> 15970.668 | F11: =Assumption!F42 -> 17364.219 | G11: =Assumption!G42 -> 18862.804 | H11: =Assumption!H42 -> 20707.305
A12: Total Expenses | B12: 48783 | C12: 50019 | D12: =SUM(D5:D11) -> 52014.438 | E12: =SUM(E5:E11) -> 55973.346 | F12: =SUM(F5:F11) -> 60783.657 | G12: =SUM(G5:G11) -> 66451.599 | H12: =SUM(H5:H11) -> 73231.266
A13: Profit before exceptional items, share of equity accounted investee and tax | B13: 13924 | C13: 14119 | D13: =D4-D12 -> 14676.01 | E13: =E4-E12 -> 15711.787 | F13: =F4-F12 -> 16806.948 | G13: =G4-G12 -> 18107.486 | H13: =H4-H12 -> 19546.595
A14: Share of equity accounted investee and tax | B14: -4 | C14: -8 | D14: =Assumption!D9 -> 0 | E14: =Assumption!E9 -> 0 | F14: =Assumption!F9 -> 0 | G14: =Assumption!G9 -> 0 | H14: =Assumption!H9 -> 0
A15: Profit before exceptional items and tax | B15: 13920 | C15: 14111 | D15: =D13-D14 -> 14676.01 | E15: =E13-E14 -> 15711.787 | F15: =F13-F14 -> 16806.948 | G15: =G13-G14 -> 18107.486 | H15: =H13-H14 -> 19546.595
A16: Exceptional items (net) | B16: 6 | C16: 305 | D16: =C16 -> 305 | E16: =D16 -> 305 | F16: =E16 -> 305 | G16: =F16 -> 305 | H16: =G16 -> 305
A17: Profit before Tax | B17: 13926 | C17: 14416 | D17: =D15+D16 -> 14981.01 | E17: =E15+E16 -> 16016.787 | F17: =F15+F16 -> 17111.948 | G17: =G15+G16 -> 18412.486 | H17: =H15+H16 -> 19851.595
A18: Current tax | B18: -3521 | C18: -3620 | D18: =Assumption!D12 -> -3761.8796 | E18: =Assumption!E12 -> -4021.9734 | F18: =Assumption!F12 -> -4296.9791 | G18: =Assumption!G12 -> -4623.5571 | H18: =Assumption!H12 -> -4984.9315
A19: Deferred tax charge | B19: -123 | C19: -124 | D19: =Assumption!D13 -> -128.85996 | E19: =Assumption!E13 -> -137.76925 | F19: =Assumption!F13 -> -147.18934 | G19: =Assumption!G13 -> -158.37599 | H19: =Assumption!H13 -> -170.75456
A20: Profit after tax | B20: 10282 | C20: 10672 | D20: =D17+D18+D19 -> 11090.27 | E20: =E17+E18+E19 -> 11857.044 | F20: =F17+F18+F19 -> 12667.779 | G20: =G17+G18+G19 -> 13630.553 | H20: =H17+H18+H19 -> 14695.909
A21: Dividend Paid | B21: 9870 | C21: 12455 | D21: =D20*C25 -> 12943.152 | E21: =E20*D25 -> 13838.033 | F21: =F20*E25 -> 14784.22 | G21: =G20*F25 -> 15907.846 | H21: =H20*G25 -> 17151.194
A22: Retained Earnings | B22: 412 | C22: -1783 | D22: =D20-D21 -> -1852.8816 | E22: =E20-E21 -> -1980.9885 | F22: =F20-F21 -> -2116.4403 | G22: =G20-G21 -> -2277.2935 | H22: =H20-H21 -> -2455.2853
A25: Payout Ratio | B25: =B21/B20 -> 0.95992997 | C25: =C21/C20 -> 1.1670727 | D25: =D21/D20 -> 1.1670727 | E25: =E21/E20 -> 1.1670727 | F25: =F21/F20 -> 1.1670727 | G25: =G21/G20 -> 1.1670727 | H25: =H21/H20 -> 1.1670727

Sheet Assumption
A1: Particulars | B1: =IS!B1 -> 2024 | C1: =B1+1 -> 2025 | D1: =C1+1 -> 2026 | E1: =D1+1 -> 2027 | F1: =E1+1 -> 2028 | G1: =F1+1 -> 2029 | H1: =G1+1 -> 2030
A2: Revenue from Operations | B2: =IS!B2 -> 61896 | C2: =IS!C2 -> 63121 | D2: =D24 -> 65571.748 | E2: =E24 -> 70443.375 | F2: =F24 -> 76199.837 | G2: =G24 -> 82987.518 | H2: =H24 -> 90986.274
A3: Other Inocme | B3: =IS!B3 -> 811 | C3: =IS!C3 -> 1017 | D3: =D26 -> 1118.7 | E3: =E26 -> 1241.757 | F3: =F26 -> 1390.7678 | G3: =G26 -> 1571.5677 | H3: =H26 -> 1791.5871
A4: Cost of Materials Consumed | B4: =IS!B5 -> 19257 | C4: =IS!C5 -> 19458 | D4: =D30 -> 20307.037 | E4: =E30 -> 21765.486 | F4: =F30 -> 23571.289 | G4: =G30 -> 25656.157 | H4: =H30 -> 28137.141
A5: Purchase of Stock in Trade | B5: =IS!B6 -> 10514 | C5: =IS!C6 -> 11272 | D5: =D33 -> 11424.016 | E5: =E33 -> 12426.186 | F5: =F33 -> 13358.641 | G5: =G33 -> 14593.781 | H5: =H33 -> 15975.632
A6: Changes in Inventories of FG and WIP | B6: =IS!B7 -> -11 | C6: =IS!C7 -> -153 | D6: =0 -> 0 | E6: =0 -> 0 | F6: =0 -> 0 | G6: =0 -> 0 | H6: =0 -> 0
A7: Employee benefits expenses | B7: =IS!B8 -> 3009 | C7: =IS!C8 -> 3077 | D7: =D36 -> 3457.3172 | E7: =E36 -> 3939.7858 | F7: =F36 -> 4552.8165 | G7: =G36 -> 5334.7627 | H7: =H36 -> 6337.6981
A8: Other Expenses | B8: =IS!B11 -> 14464 | C8: =IS!C11 -> 14615 | D8: =D42 -> 15018.446 | E8: =E42 -> 15970.668 | F8: =F42 -> 17364.219 | G8: =G42 -> 18862.804 | H8: =H42 -> 20707.305
A9: Share of equity accounted investee and tax | B9: =IS!B14 -> -4 | C9: =IS!C14 -> -8 | D9: =0 -> 0 | E9: =0 -> 0 | F9: =0 -> 0 | G9: =0 -> 0 | H9: =0 -> 0
A10: Exceptional items (net) | B10: =IS!B16 -> 6 | C10: =IS!C16 -> 305 | D10: =C10 -> 305 | E10: =D10 -> 305 | F10: =E10 -> 305 | G10: =F10 -> 305 | H10: =G10 -> 305
A11: Tax | B11: =SUM(B12:B13) -> -3644 | C11: =SUM(C12:C13) -> -3744 | D11: =D66 -> -3890.7396 | E11: =E66 -> -4159.7426 | F11: =F66 -> -4444.1685 | G11: =G66 -> -4781.9331 | H11: =H66 -> -5155.6861
A12: Current Tax | B12: =IS!B18 -> -3521 | C12: =IS!C18 -> -3620 | D12: =D68 -> -3761.8796 | E12: =E68 -> -4021.9734 | F12: =F68 -> -4296.9791 | G12: =G68 -> -4623.5571 | H12: =H68 -> -4984.9315
A13: Deferred tax charge | B13: =IS!B19 -> -123 | C13: =IS!C19 -> -124 | D13: =D70 -> -128.85996 | E13: =E70 -> -137.76925 | F13: =F70 -> -147.18934 | G13: =G70 -> -158.37599 | H13: =H70 -> -170.75456
A15: Revenue Drivers | B15: =B1 -> 2024 | C15: =C1 -> 2025 | D15: =D1 -> 2026 | E15: =E1 -> 2027 | F15: =F1 -> 2028 | G15: =G1 -> 2029 | H15: =H1 -> 2030
A16: Home Care | B16: 21882 | C16: 22972 | D16: =C16*(1+D17) -> 25269.2 | E16: =D16*(1+E17) -> 27922.466 | F16: =E16*(1+F17) -> 30993.937 | G16: =F16*(1+G17) -> 34558.24 | H16: =G16*(1+H17) -> 38705.229
A17: Growth % | B17: 0.031 | C17: =C16/B16-1 -> 0.049812631 | D17: 0.1 | E17: =D17+0.5% -> 0.105 | F17: =E17+0.5% -> 0.11 | G17: =F17+0.5% -> 0.115 | H17: =G17+0.5% -> 0.12 | I17: Industry Report (McKinsey, stastica, BCG etc)
A18: Beauty and Personal Care | B18: 22448 | C18: 22241 | D18: =C18*(1+D19) -> 23353.05 | E18: =D18*(1+E19) -> 24754.233 | F18: =E18*(1+F19) -> 26487.029 | G18: =F18*(1+G19) -> 28605.992 | H18: =G18*(1+H19) -> 31180.531
A19: Growth % | B19: 0.019 | C19: =C18/B18-1 -> -0.0092213115 | D19: 0.05 | E19: =D19+1% -> 0.06 | F19: =E19+1% -> 0.07 | G19: =F19+1% -> 0.08 | H19: =G19+1% -> 0.09 | I19: Industry Report (McKinsey, stastica, BCG etc)
A20: Foods and Refreshment | B20: 15291 | C20: 15291 | D20: =C20*(1+D21) -> 15872.058 | E20: =D20*(1+E21) -> 16554.556 | F20: =E20*(1+F21) -> 17349.175 | G20: =F20*(1+G21) -> 18268.681 | H20: =G20*(1+H21) -> 19328.265
A21: Growth % | B21: 0.028 | C21: =C20/B20-1 -> 0 | D21: 0.038 | E21: =D21+0.5% -> 0.043 | F21: =E21+0.5% -> 0.048 | G21: =F21+0.5% -> 0.053 | H21: =G21+0.5% -> 0.058 | I21: Industry Report (McKinsey, stastica, BCG etc)
A22: Others (includes Exports, Consigments, etc) | B22: 2275 | C22: 962 | D22: =C22*(1+D23) -> 1077.44 | E22: =D22*(1+E23) -> 1212.12 | F22: =E22*(1+F23) -> 1369.6956 | G22: =F22*(1+G23) -> 1554.6045 | H22: =G22*(1+H23) -> 1772.2491
A23: Growth % | B23: -0.075 | C23: =C22/B22-1 -> -0.57714286 | D23: 0.12 | E23: =D23+0.5% -> 0.125 | F23: =E23+0.5% -> 0.13 | G23: =F23+0.5% -> 0.135 | H23: =G23+0.5% -> 0.14 | I23: Industry Report (McKinsey, stastica, BCG etc)
A24: Revenue | B24: =SUM(B16,B18,B20,B22) -> 61896 | C24: =SUM(C16,C18,C20,C22) -> 61466 | D24: =SUM(D16,D18,D20,D22) -> 65571.748 | E24: =SUM(E16,E18,E20,E22) -> 70443.375 | F24: =SUM(F16,F18,F20,F22) -> 76199.837 | G24: =SUM(G16,G18,G20,G22) -> 82987.518 | H24: =SUM(H16,H18,H20,H22) -> 90986.274
A25: Growth % | B25: 0.022 | C25: =C24/B24-1 -> -0.0069471371 | D25: =D24/C24-1 -> 0.066797059 | E25: =E24/D24-1 -> 0.074294611 | F25: =F24/E24-1 -> 0.081717576 | G25: =G24/F24-1 -> 0.08907736 | H25: =H24/G24-1 -> 0.096385052 | I25: Industry Report (McKinsey, stastica, BCG etc)
A26: Other Inocme | B26: =B3 -> 811 | C26: =C3 -> 1017 | D26: =C26*(1+D27) -> 1118.7 | E26: =D26*(1+E27) -> 1241.757 | F26: =E26*(1+F27) -> 1390.7678 | G26: =F26*(1+G27) -> 1571.5677 | H26: =G26*(1+H27) -> 1791.5871
A27: Growth % | C27: =C26/B26-1 -> 0.2540074 | D27: 0.1 | E27: =D27+1% -> 0.11 | F27: =E27+1% -> 0.12 | G27: =F27+1% -> 0.13 | H27: =G27+1% -> 0.14 | I27: Industry Report (McKinsey, stastica, BCG etc)
A29: Cost Drivers
A30: Cost of materials consumed | B30: =B4 -> 19257 | C30: =C4 -> 19458 | D30: =D31*D2 -> 20307.037 | E30: =E31*E2 -> 21765.486 | F30: =F31*F2 -> 23571.289 | G30: =G31*G2 -> 25656.157 | H30: =H31*H2 -> 28137.141
A31: As % of Revenue | B31: =B30/B24 -> 0.31111865 | C31: =C30/C2 -> 0.30826508 | D31: =AVERAGE(B31:C31) -> 0.30969186 | E31: =AVERAGE(C31:D31) -> 0.30897847 | F31: =AVERAGE(D31:E31) -> 0.30933517 | G31: =AVERAGE(E31:F31) -> 0.30915682 | H31: =AVERAGE(F31:G31) -> 0.30924599
A33: Purchases of stock-in-trade | B33: =B5 -> 10514 | C33: =C5 -> 11272 | D33: =D2*D34 -> 11424.016 | E33: =E2*E34 -> 12426.186 | F33: =F2*F34 -> 13358.641 | G33: =G2*G34 -> 14593.781 | H33: =H2*H34 -> 15975.632
A34: As % of Revenue | B34: =B33/B2 -> 0.16986558 | C34: =C33/C2 -> 0.17857765 | D34: =AVERAGE(B34:C34) -> 0.17422162 | E34: =AVERAGE(C34:D34) -> 0.17639963 | F34: =AVERAGE(D34:E34) -> 0.17531063 | G34: =AVERAGE(E34:F34) -> 0.17585513 | H34: =AVERAGE(F34:G34) -> 0.17558288
A36: Employee benefits expenses | B36: =B7 -> 3009 | C36: =C7 -> 3077 | D36: =D37*D39 -> 3457.3172 | E36: =E37*E39 -> 3939.7858 | F36: =F37*F39 -> 4552.8165 | G36: =G37*G39 -> 5334.7627 | H36: =H37*H39 -> 6337.6981
A37: No. of Employee | B37: 7215 | C37: 8202 | D37: =C37*(1+D38) -> 8694.12 | E37: =D37*(1+E38) -> 9302.7084 | F37: =E37*(1+F38) -> 10046.925 | G37: =F37*(1+G38) -> 10951.148 | H37: =G37*(1+H38) -> 12046.263 | I37: Statuatory Report - in annual report - Section 20a
A38: Growth % | C38: =C37/B37-1 -> 0.13679834 | D38: 0.06 | E38: =D38+1% -> 0.07 | F38: =E38+1% -> 0.08 | G38: =F38+1% -> 0.09 | H38: =G38+1% -> 0.1
A39: Revenue Per employee (in cr) | B39: =B36/B37 -> 0.41704782 | C39: =C36/C37 -> 0.3751524 | D39: =C39*(1+D40) -> 0.39766155 | E39: =D39*(1+E40) -> 0.42350955 | F39: =E39*(1+F40) -> 0.45315521 | G39: =F39*(1+G40) -> 0.48714186 | H39: =G39*(1+H40) -> 0.5261132
A40: Growth % | C40: =C39/B39-1 -> -0.1004571 | D40: 0.06 | E40: =D40+0.5% -> 0.065 | F40: =E40+0.5% -> 0.07 | G40: =F40+0.5% -> 0.075 | H40: =G40+0.5% -> 0.08
A42: Other Expense | B42: =B8 -> 14464 | C42: =C8 -> 14615 | D42: =SUM(D44,D46,D48,D50,D52,D54,D56,D58,D60,D62,D64) -> 15018.446 | E42: =SUM(E44,E46,E48,E50,E52,E54,E56,E58,E60,E62,E64) -> 15970.668 | F42: =SUM(F44,F46,F48,F50,F52,F54,F56,F58,F60,F62,F64) -> 17364.219 | G42: =SUM(G44,G46,G48,G50,G52,G54,G56,G58,G60,G62,G64) -> 18862.804 | H42: =SUM(H44,H46,H48,H50,H52,H54,H56,H58,H60,H62,H64) -> 20707.305
A43: As % of Revenue | B43: =B42/B2 -> 0.23368231 | C43: =C42/C2 -> 0.23153942 | D43: =D42/D2 -> 0.22903836 | E43: =E42/E2 -> 0.22671639 | F43: =F42/F2 -> 0.22787738 | G43: =G42/G2 -> 0.22729688 | H43: =H42/H2 -> 0.22758713
A44: Advertising & Promotion | B44: 6489 | C44: 6028 | D44: =D45*D2 -> 6568.1996 | E44: =E45*E2 -> 6891.7309 | F44: =F45*F2 -> 7543.851 | G44: =G45*G2 -> 8167.4036 | H44: =H45*H2 -> 8981.1702
A45: As % of Revenue | B45: =B44/B2 -> 0.10483715 | C45: =C44/C2 -> 0.095499121 | D45: =AVERAGE(B45:C45) -> 0.10016813 | E45: =AVERAGE(C45:D45) -> 0.097833627 | F45: =AVERAGE(D45:E45) -> 0.09900088 | G45: =AVERAGE(E45:F45) -> 0.098417254 | H45: =AVERAGE(F45:G45) -> 0.098709067
...

Sheet BS
A1: Particulars | B1: 2024 | C1: =B1+1 -> 2025 | D1: 2026 | E1: =D1+1 -> 2027 | F1: =E1+1 -> 2028 | G1: =F1+1 -> 2029 | H1: =G1+1 -> 2030
A2: Assets
A3: Non-Current Assets
A4: Property, Plant and equipment | B4: 8031 | C4: 8625 | D4: ='CAPEX Schedule '!D2 -> 7887.5505 | E4: ='CAPEX Schedule '!E2 -> 7111.7964 | F4: ='CAPEX Schedule '!F2 -> 6296.5389 | G4: ='CAPEX Schedule '!G2 -> 5440.5417 | H4: ='CAPEX Schedule '!H2 -> 4542.5299
A5: Capital work-in-progress | B5: 1025 | C5: 1009 | D5: =Assumption!D75 -> 1009 | E5: =Assumption!E75 -> 1009 | F5: =Assumption!F75 -> 1009 | G5: =Assumption!G75 -> 1009 | H5: =Assumption!H75 -> 1009
A6: Goodwill | B6: 17466 | C6: 17466 | D6: =Assumption!D76 -> 17466 | E6: =Assumption!E76 -> 17466 | F6: =Assumption!F76 -> 17466 | G6: =Assumption!G76 -> 17466 | H6: =Assumption!H76 -> 17466
A7: Other intangible assets | B7: 28247 | C7: 28243 | D7: ='CAPEX Schedule '!D5 -> 29422.398 | E7: ='CAPEX Schedule '!E5 -> 30638.283 | F7: ='CAPEX Schedule '!F5 -> 31891.799 | G7: ='CAPEX Schedule '!G5 -> 33184.122 | H7: ='CAPEX Schedule '!H5 -> 34516.467
A8: Investments accounted for using equity method | B8: 65 | C8: 57 | D8: =Assumption!D77 -> 57 | E8: =Assumption!E77 -> 57 | F8: =Assumption!F77 -> 57 | G8: =Assumption!G77 -> 57 | H8: =Assumption!H77 -> 57
A9: Investments | B9: 2 | C9: 2 | D9: 2 | E9: 2 | F9: 2 | G9: 2 | H9: 2
A10: Loans | B10: 102 | C10: 87 | D10: =Assumption!D78 -> 87 | E10: =Assumption!E78 -> 87 | F10: =Assumption!F78 -> 87 | G10: =Assumption!G78 -> 87 | H10: =Assumption!H78 -> 87
A11: Other financial assets | B11: 760 | C11: 763 | D11: =Assumption!D79 -> 763 | E11: =Assumption!E79 -> 763 | F11: =Assumption!F79 -> 763 | G11: =Assumption!G79 -> 763 | H11: =Assumption!H79 -> 763
A12: Deffered tax assets (net) | B12: 10 | C12: 17 | D12: =Assumption!D80 -> 17 | E12: =Assumption!E80 -> 17 | F12: =Assumption!F80 -> 17 | G12: =Assumption!G80 -> 17 | H12: =Assumption!H80 -> 17
A13: Non-current tax assets (net) | B13: 1175 | C13: 1199 | D13: =Assumption!D81 -> 1199 | E13: =Assumption!E81 -> 1199 | F13: =Assumption!F81 -> 1199 | G13: =Assumption!G81 -> 1199 | H13: =Assumption!H81 -> 1199
A14: Other non-current assets | B14: 292 | C14: 360 | D14: =Assumption!D82 -> 360 | E14: =Assumption!E82 -> 360 | F14: =Assumption!F82 -> 360 | G14: =Assumption!G82 -> 360 | H14: =Assumption!H82 -> 360
A15: Current Assests
A16: Inventories | B16: 4022 | C16: 4415 | D16: ='Working Cap Schedule '!D3 -> 4423.6338 | E16: ='Working Cap Schedule '!E3 -> 4839.7249 | F16: ='Working Cap Schedule '!F3 -> 5187.9233 | G16: ='Working Cap Schedule '!G3 -> 5675.8022 | H16: ='Working Cap Schedule '!H3 -> 6208.7475
A17: Investments | B17: 4558 | C17: 3751 | D17: ='Working Cap Schedule '!D4 -> 4362.6589 | E17: ='Working Cap Schedule '!E4 -> 4436.4586 | F17: ='Working Cap Schedule '!F4 -> 4934.3843 | G17: ='Working Cap Schedule '!G4 -> 5300.2016 | H17: ='Working Cap Schedule '!H4 -> 5851.4771
A18: Trade receivables | B18: 2997 | C18: 3819 | D18: ='Working Cap Schedule '!D5 -> 3571.1283 | E18: ='Working Cap Schedule '!E5 -> 4049.2342 | F18: ='Working Cap Schedule '!F5 -> 4265.0383 | G18: ='Working Cap Schedule '!G5 -> 4707.6274 | H18: ='Working Cap Schedule '!H5 -> 5127.0167
A19: Cash and cash equivalents | B19: 825 | C19: 6071
A20: Bank balances other than cash equivalents | B20: 6734 | C20: 1483 | D20: ='Working Cap Schedule '!D6 -> 3952.2697 | E20: ='Working Cap Schedule '!E6 -> 4438.8976 | F20: ='Working Cap Schedule '!F6 -> 5010.4003 | G20: ='Working Cap Schedule '!G6 -> 5684.0766 | H20: ='Working Cap Schedule '!H6 -> 6481.214
A21: Loans | B21: 38 | C21: 46 | D21: ='Working Cap Schedule '!D7 -> 44.021334 | E21: ='Working Cap Schedule '!E7 -> 49.314065 | F21: ='Working Cap Schedule '!F7 -> 52.250175 | G21: ='Working Cap Schedule '!G7 -> 57.500053 | H21: ='Working Cap Schedule '!H7 -> 62.715711
A22: Other financial assets (current) | B22: 1425 | C22: 1488 | D22: ='Working Cap Schedule '!D8 -> 1527.6991 | E22: ='Working Cap Schedule '!E8 -> 1650.9075 | F22: ='Working Cap Schedule '!F8 -> 1780.5647 | G22: ='Working Cap Schedule '!G8 -> 1942.032 | H22: ='Working Cap Schedule '!H8 -> 2127.6474
A23: Other financial assets | B23: 713 | C23: 955 | D23: ='Working Cap Schedule '!D9 -> 873.71057 | E23: ='Working Cap Schedule '!E9 -> 1002.2038 | F23: ='Working Cap Schedule '!F9 -> 1049.713 | G23: ='Working Cap Schedule '!G9 -> 1161.9445 | H23: ='Working Cap Schedule '!H9 -> 1263.6733
A24: Assets held for sale | B24: 12 | C24: 23 | D24: ='Working Cap Schedule '!D10 -> 18.302816 | E24: ='Working Cap Schedule '!E10 -> 22.66537 | F24: ='Working Cap Schedule '!F10 -> 22.893464 | G24: ='Working Cap Schedule '!G10 -> 25.81712 | H24: ='Working Cap Schedule '!H10 -> 27.820701
A25: Total Assets | B25: =B16+B17+B18+B20+B21+B22+B23+B24 -> 20499 | C25: =C16+C17+C18+C20+C21+C22+C23+C24 -> 15980 | D25: =D16+D17+D18+D20+D21+D22+D23+D24 -> 18773.425 | E25: =E16+E17+E18+E20+E21+E22+E23+E24 -> 20489.406 | F25: =F16+F17+F18+F20+F21+F22+F23+F24 -> 22303.168 | G25: =G16+G17+G18+G20+G21+G22+G23+G24 -> 24555.002 | H25: =H16+H17+H18+H20+H21+H22+H23+H24 -> 27150.312
A26: Equity And Liabilities
A27: Equity
A28: Equity share capital | B28: 235 | C28: 235 | D28: 235 | E28: 235 | F28: 235 | G28: 235 | H28: 235
A29: Other equity | B29: 50983 | C29: 49167 | D29: =C29+IS!D22 -> 47314.118 | E29: =D29+IS!E22 -> 45333.13 | F29: =E29+IS!F22 -> 43216.69 | G29: =F29+IS!G22 -> 40939.396 | H29: =G29+IS!H22 -> 38484.111
A30: Non-controlling interests | B30: 205 | C30: 207 | D30: 207 | E30: 207 | F30: 207 | G30: 207 | H30: 207
A31: Liabilities
A32: Non-current Liabilities
A33: Lease Liabilities | B33: 1106 | C33: 1243 | D33: ='Debt Schedule'!D6 -> 1280.7353 | E33: ='Debt Schedule'!E6 -> 1318.4706 | F33: ='Debt Schedule'!F6 -> 1356.2058 | G33: ='Debt Schedule'!G6 -> 1393.9411 | H33: ='Debt Schedule'!H6 -> 1431.6764
A34: Other financial liabilities (non-current) | B34: 718 | C34: 680 | D34: =Assumption!D83 -> 680 | E34: =Assumption!E83 -> 680 | F34: =Assumption!F83 -> 680 | G34: =Assumption!G83 -> 680 | H34: =Assumption!H83 -> 680
A35: Provisions (non-current) | B35: 1576 | C35: 1528 | D35: =Assumption!D84 -> 1528 | E35: =Assumption!E84 -> 1528 | F35: =Assumption!F84 -> 1528 | G35: =Assumption!G84 -> 1528 | H35: =Assumption!H84 -> 1528
A36: Deferred tax liabilities (net) | B36: 6557 | C36: 6685 | D36: =Assumption!D85 -> 6685 | E36: =Assumption!E85 -> 6685 | F36: =Assumption!F85 -> 6685 | G36: =Assumption!G85 -> 6685 | H36: =Assumption!H85 -> 6685
A37: Non-current tax liabilities (net) | B37: 4243 | C37: 3598 | D37: =Assumption!D86 -> 3598 | E37: =Assumption!E86 -> 3598 | F37: =Assumption!F86 -> 3598 | G37: =Assumption!G86 -> 3598 | H37: =Assumption!H86 -> 3598
A38: Current Liabilities
A39: Borrowings | B39: 13 | C39: 1 | D39: ='Debt Schedule'!D4 -> 0 | E39: ='Debt Schedule'!E4 -> 0 | F39: ='Debt Schedule'!F4 -> 0 | G39: ='Debt Schedule'!G4 -> 0 | H39: ='Debt Schedule'!H4 -> 0
A40: Lease Liabilities | B40: 365 | C40: 404 | D40: ='Debt Schedule'!D7 -> 416.26472 | E40: ='Debt Schedule'!E7 -> 428.52945 | F40: ='Debt Schedule'!F7 -> 440.79417 | G40: ='Debt Schedule'!G7 -> 453.05889 | H40: ='Debt Schedule'!H7 -> 465.32362
...

Sheet Sheet4
A1: Particulars | B1: 2024 | C1: =B1+1 -> 2025 | D1: 2026 | E1: =D1+1 -> 2027 | F1: =E1+1 -> 2028 | G1: =F1+1 -> 2029 | H1: =G1+1 -> 2030
A2: Operating Activities
A3: Net Income | B3: =IS!B17 -> 13926 | C3: =IS!C17 -> 14416 | D3: =IS!D17 -> 14981.01 | E3: =IS!E17 -> 16016.787 | F3: =IS!F17 -> 17111.948 | G3: =IS!G17 -> 18412.486 | H3: =IS!H17 -> 19851.595
A4: Depreciation & Amortization | B4: =IS!B10 -> 1216 | C4: =IS!C10 -> 1355 | D4: =IS!D10 -> 1413.0518 | E4: =IS!E10 -> 1472.9202 | F4: =IS!F10 -> 1534.6623 | G4: =IS!G10 -> 1598.3365 | H4: =IS!H10 -> 1664.0034
A5: Minority Interest | B5: =BS!B30 -> 205 | C5: =BS!C30 -> 207 | D5: =BS!D30 -> 207 | E5: =BS!E30 -> 207 | F5: =BS!F30 -> 207 | G5: =BS!G30 -> 207 | H5: =BS!H30 -> 207
A6: Change in Working Capital | B6: ='Working Cap Schedule '!B19 -> 0 | C6: ='Working Cap Schedule '!C19 -> -8150 | D6: ='Working Cap Schedule '!D19 -> 4913.0043 | E6: ='Working Cap Schedule '!E19 -> -800.03149 | F6: ='Working Cap Schedule '!F19 -> 1260.8461 | G6: ='Working Cap Schedule '!G19 -> 295.86784 | H6: ='Working Cap Schedule '!H19 -> 998.53566
A7: Change in Other Long-Term Assets & Liabilities | C7: ='Working Cap Schedule '!C50 -> -100 | D7: ='Working Cap Schedule '!D50 -> 0 | E7: ='Working Cap Schedule '!E50 -> 0 | F7: ='Working Cap Schedule '!F50 -> 0 | G7: ='Working Cap Schedule '!G50 -> 0 | H7: ='Working Cap Schedule '!H50 -> 0
A8: Other
A9: Cash Flow from Operating Activities | B9: =SUM(B3:B8) -> 15347 | C9: =SUM(C3:C8) -> 7728 | D9: =SUM(D3:D8) -> 21514.066 | E9: =SUM(E3:E8) -> 16896.676 | F9: =SUM(F3:F8) -> 20114.456 | G9: =SUM(G3:G8) -> 20513.69 | H9: =SUM(H3:H8) -> 22721.134
A11: Investing Activities
A12: Capital Expenditures | C12: ='CAPEX Schedule '!C25 -> 2529 | D12: ='CAPEX Schedule '!D25 -> 1855 | E12: ='CAPEX Schedule '!E25 -> 1913.0518 | F12: ='CAPEX Schedule '!F25 -> 1972.9202 | G12: ='CAPEX Schedule '!G25 -> 2034.6623 | H12: ='CAPEX Schedule '!H25 -> 2098.3365
A13: Asset Sales
A14: Additions to Goodwill / Intangibles
A15: Other
A16: Cash Flow from Investing Activities | C16: =SUM(C12:C15) -> 2529 | D16: =SUM(D12:D15) -> 1855 | E16: =SUM(E12:E15) -> 1913.0518 | F16: =SUM(F12:F15) -> 1972.9202 | G16: =SUM(G12:G15) -> 2034.6623 | H16: =SUM(H12:H15) -> 2098.3365
A18: Financing Activities
A19: Proceeds from / (Repayment of) Revolver
A20: Proceeds from / (Repayment of) Long Term Debt
A21: Issuance / (Repurchase of) Equity
A22: Dividends
A23: Other
A24: Cash Flow from Investing Activities
A27: Effects of Exchange Rates on Cash
A28: Net Change in Cash
A29: Beginning Cash Balance
A30: Ending Cash Balance

Sheet Debt Schedule
A1: Debt Schedule | B1: 2024 | C1: =B1+1 -> 2025 | D1: 2026 | E1: =D1+1 -> 2027 | F1: =E1+1 -> 2028 | G1: =F1+1 -> 2029 | H1: =G1+1 -> 2030
A2: Long Term Borrowings | B2: 0 | C2: 0 | D2: =C2 -> 0 | E2: =D2 -> 0 | F2: =E2 -> 0 | G2: =F2 -> 0 | H2: =G2 -> 0
A3: Short Term Borrowings | B3: =BS!B39 -> 13 | C3: =BS!C39 -> 1 | D3: 0 | E3: 0 | F3: 0 | G3: 0 | H3: 0
A4: Total Borrowings | B4: =SUM(B2:B3) -> 13 | C4: =SUM(C2:C3) -> 1 | D4: =SUM(D2:D3) -> 0 | E4: =SUM(E2:E3) -> 0 | F4: =SUM(F2:F3) -> 0 | G4: =SUM(G2:G3) -> 0 | H4: =SUM(H2:H3) -> 0
A6: Long Term Lease | B6: =BS!B33 -> 1106 | C6: =BS!C33 -> 1243 | D6: =C$6/C$8*D$8 -> 1280.7353 | E6: =D$6/D$8*E$8 -> 1318.4706 | F6: =E$6/E$8*F$8 -> 1356.2058 | G6: =F$6/F$8*G$8 -> 1393.9411 | H6: =G$6/G$8*H$8 -> 1431.6764
A7: Short Term Lease | B7: =BS!B40 -> 365 | C7: =BS!C40 -> 404 | D7: =C$7/C$8*D$8 -> 416.26472 | E7: =D$7/D$8*E$8 -> 428.52945 | F7: =E$7/E$8*F$8 -> 440.79417 | G7: =F$7/F$8*G$8 -> 453.05889 | H7: =G$7/G$8*H$8 -> 465.32362
A8: Total Lease | B8: =SUM(B6:B7) -> 1471 | C8: =SUM(C6:C7) -> 1647 | D8: =C8+D22 -> 1697 | E8: =D8+E22 -> 1747 | F8: =E8+F22 -> 1797 | G8: =F8+G22 -> 1847 | H8: =G8+H22 -> 1897
A10: Interest expense on loan on bank overdraft, security deposit and others | B10: 4 | C10: 3 | D10: =C10 -> 3 | E10: =D10 -> 3 | F10: =E10 -> 3 | G10: =F10 -> 3 | H10: =G10 -> 3
A11: Net interet on the net defined liability | B11: 24 | C11: 23 | D11: =C11 -> 23 | E11: =D11 -> 23 | F11: =E11 -> 23 | G11: =F11 -> 23 | H11: =G11 -> 23
A12: Unwinding of discount on provisions and liabilities | B12: 20 | C12: 16 | D12: =C12 -> 16 | E12: =D12 -> 16 | F12: =E12 -> 16 | G12: =F12 -> 16 | H12: =G12 -> 16
A13: Unwinding of discount on employee and ex-employee related liabilities | B13: 9 | C13: 11 | D13: =C13 -> 11 | E13: =D13 -> 11 | F13: =E13 -> 11 | G13: =F13 -> 11 | H13: =G13 -> 11
A14: Interest on Lease Liabilities | B14: 106 | C14: 127 | D14: =D19*D8 -> 126.57051 | E14: =E19*E8 -> 130.29975 | F14: =F19*F8 -> 134.02899 | G14: =G19*G8 -> 137.75824 | H14: =H19*H8 -> 141.48748
A15: Interest on taxes and others | B15: 171 | C15: 215 | D15: =C15 -> 215 | E15: =D15 -> 215 | F15: =E15 -> 215 | G15: =F15 -> 215 | H15: =G15 -> 215
A16: Total Interest | B16: =SUM(B10:B15) -> 334 | C16: =SUM(C10:C15) -> 395 | D16: =SUM(D10:D15) -> 394.57051 | E16: =SUM(E10:E15) -> 398.29975 | F16: =SUM(F10:F15) -> 402.02899 | G16: =SUM(G10:G15) -> 405.75824 | H16: =SUM(H10:H15) -> 409.48748
A18: Cost of Borrowing (%) | B18: =0 -> 0 | C18: =0 -> 0 | D18: =0 -> 0 | E18: =0 -> 0 | F18: =0 -> 0 | G18: =0 -> 0 | H18: =0 -> 0
A19: Cost of Lease (%) | B19: =B14/B8 -> 0.072059823 | C19: =C14/C8 -> 0.077109897 | D19: =AVERAGE(B19:C19) -> 0.07458486 | E19: =D19 -> 0.07458486 | F19: =E19 -> 0.07458486 | G19: =F19 -> 0.07458486 | H19: =G19 -> 0.07458486
A20: Weighted Average Cost of Borrowing | C20: =C16/(C8+C4) -> 0.23968447 | D20: =D16/(D8+D4) -> 0.23251061 | E20: =E16/(E8+E4) -> 0.2279907 | F20: =F16/(F8+F4) -> 0.22372231 | G20: =G16/(G8+G4) -> 0.21968502 | H20: =H16/(H8+H4) -> 0.21586056
A21: Net Borrowing Raised | B21: 0 | C21: =C4-B4 -> -12 | D21: =D4-C4 -> -1 | E21: =E4-D4 -> 0 | F21: =F4-E4 -> 0 | G21: =G4-F4 -> 0 | H21: =H4-G4 -> 0
A22: Net Lease added | C22: =C8-B8 -> 176 | D22: =50 -> 50 | E22: =50 -> 50 | F22: =50 -> 50 | G22: =50 -> 50 | H22: =50 -> 50
A25: Assumptions:
A26: Long and Short Term borrowings are assumed to be 0
A27: 50 Cr lease is added very year from 2026 onwards

Sheet Working Cap Schedule 
A1: Working Capital Schedule | B1: 2024 | C1: =B1+1 -> 2025 | D1: 2026 | E1: =D1+1 -> 2027 | F1: =E1+1 -> 2028 | G1: =F1+1 -> 2029 | H1: =G1+1 -> 2030
A2: Current Assets Other than Cash
A3: Inventories | B3: =BS!B16 -> 4022 | C3: =BS!C16 -> 4415 | D3: =D22*IS!D2/365 -> 4423.6338 | E3: =E22*IS!E2/365 -> 4839.7249 | F3: =F22*IS!F2/365 -> 5187.9233 | G3: =G22*IS!G2/365 -> 5675.8022 | H3: =H22*IS!H2/365 -> 6208.7475
A4: Investments | B4: =BS!B17 -> 4558 | C4: =BS!C17 -> 3751 | D4: =D23*IS!D2/365 -> 4362.6589 | E4: =E23*IS!E2/365 -> 4436.4586 | F4: =F23*IS!F2/365 -> 4934.3843 | G4: =G23*IS!G2/365 -> 5300.2016 | H4: =H23*IS!H2/365 -> 5851.4771
A5: Trade Receivables | B5: =BS!B18 -> 2997 | C5: =BS!C18 -> 3819 | D5: =D24*IS!D2/365 -> 3571.1283 | E5: =E24*IS!E2/365 -> 4049.2342 | F5: =F24*IS!F2/365 -> 4265.0383 | G5: =G24*IS!G2/365 -> 4707.6274 | H5: =H24*IS!H2/365 -> 5127.0167
A6: Bank balances other than cash equivalent | B6: =BS!B20 -> 6734 | C6: =BS!C20 -> 1483 | D6: =D25*IS!D2/365 -> 3952.2697 | E6: =E25*IS!E2/365 -> 4438.8976 | F6: =F25*IS!F2/365 -> 5010.4003 | G6: =G25*IS!G2/365 -> 5684.0766 | H6: =H25*IS!H2/365 -> 6481.214
A7: Loans | B7: =BS!B21 -> 38 | C7: =BS!C21 -> 46 | D7: =D26*IS!D2/365 -> 44.021334 | E7: =E26*IS!E2/365 -> 49.314065 | F7: =F26*IS!F2/365 -> 52.250175 | G7: =G26*IS!G2/365 -> 57.500053 | H7: =H26*IS!H2/365 -> 62.715711
A8: Other financial assets (current) | B8: =BS!B22 -> 1425 | C8: =BS!C22 -> 1488 | D8: =D27*IS!D2/365 -> 1527.6991 | E8: =E27*IS!E2/365 -> 1650.9075 | F8: =F27*IS!F2/365 -> 1780.5647 | G8: =G27*IS!G2/365 -> 1942.032 | H8: =H27*IS!H2/365 -> 2127.6474
A9: Other financial assets | B9: =BS!B23 -> 713 | C9: =BS!C23 -> 955 | D9: =D28*IS!D2/365 -> 873.71057 | E9: =E28*IS!E2/365 -> 1002.2038 | F9: =F28*IS!F2/365 -> 1049.713 | G9: =G28*IS!G2/365 -> 1161.9445 | H9: =H28*IS!H2/365 -> 1263.6733
A10: Assets held for sale | B10: =BS!B24 -> 12 | C10: =BS!C24 -> 23 | D10: =D29*IS!D2/365 -> 18.302816 | E10: =E29*IS!E2/365 -> 22.66537 | F10: =F29*IS!F2/365 -> 22.893464 | G10: =G29*IS!G2/365 -> 25.81712 | H10: =H29*IS!H2/365 -> 27.820701
A11: Current Liabilities
A12: Trade payables - micro & small enterprises | B12: =BS!B41 -> 250 | C12: =BS!C41 -> 263 | D12: =D32*IS!D2/365 -> 269.02888 | E12: =E32*IS!E2/365 -> 291.26284 | F12: =F32*IS!F2/365 -> 313.84906 | G12: =G32*IS!G2/365 -> 342.46756 | H12: =H32*IS!H2/365 -> 375.1136
A13: Trade payables - others | B13: =BS!B42 -> 10236 | C13: =BS!C42 -> 11052 | D13: =D33*IS!D2/365 -> 11162.49 | E13: =E33*IS!E2/365 -> 12162.947 | F13: =F33*IS!F2/365 -> 13064.309 | G13: =G33*IS!G2/365 -> 14278.448 | H13: =H33*IS!H2/365 -> 15627.046
A14: Other financial liabilities | B14: =BS!B43 -> 868 | C14: =BS!C43 -> 1280 | D14: =D34*IS!D2/365 -> 1124.6222 | E14: =E34*IS!E2/365 -> 1318.3312 | F14: =F34*IS!F2/365 -> 1366.4834 | G14: =G34*IS!G2/365 -> 1520.649 | H14: =H34*IS!H2/365 -> 1649.4319
A15: Other current liabilities | B15: =BS!B44 -> 807 | C15: =BS!C44 -> 959 | D15: =D35*IS!D2/365 -> 925.57936 | E15: =E35*IS!E2/365 -> 1032.297 | F15: =F35*IS!F2/365 -> 1096.1271 | G15: =G35*IS!G2/365 -> 1204.9448 | H15: =H35*IS!H2/365 -> 1314.956
A16: Provisions (current) | B16: =BS!B45 -> 340 | C16: =BS!C45 -> 675 | D16: =D36*IS!D2/365 -> 530.69944 | E16: =E36*IS!E2/365 -> 661.71559 | F16: =F36*IS!F2/365 -> 666.25318 | G16: =G36*IS!G2/365 -> 752.57563 | H16: =H36*IS!H2/365 -> 810.32553
A17: Current Tax Liabilities | B17: =BS!B46 -> 0 | C17: =BS!C46 -> 1903 | D17: =D37*IS!D2/365 -> 0 | E17: =E37*IS!E2/365 -> 1061.8791 | F17: =F37*IS!F2/365 -> 574.32665 | G17: =G37*IS!G2/365 -> 938.22923 | H17: =H37*IS!H2/365 -> 857.21709
A18: Net Working Capital | B18: =SUM(B3:B10)-SUM(B12:B17) -> 7998 | C18: =SUM(C3:C10)-SUM(C12:C17) -> -152 | D18: =SUM(D3:D10)-SUM(D12:D17) -> 4761.0043 | E18: =SUM(E3:E10)-SUM(E12:E17) -> 3960.9728 | F18: =SUM(F3:F10)-SUM(F12:F17) -> 5221.8189 | G18: =SUM(G3:G10)-SUM(G12:G17) -> 5517.6868 | H18: =SUM(H3:H10)-SUM(H12:H17) -> 6516.2224
A19: Changes in NWC | C19: =C18-B18 -> -8150 | D19: =D18-C18 -> 4913.0043 | E19: =E18-D18 -> -800.03149 | F19: =F18-E18 -> 1260.8461 | G19: =G18-F18 -> 295.86784 | H19: =H18-G18 -> 998.53566
A21: Current Assets in days of sales:
A22: Inventories | B22: =B3/IS!B2*365 -> 23.717688 | C22: =C3/IS!C2*365 -> 25.529935 | D22: =AVERAGE(B22:C22) -> 24.623811 | E22: =AVERAGE(C22:D22) -> 25.076873 | F22: =AVERAGE(D22:E22) -> 24.850342 | G22: =AVERAGE(E22:F22) -> 24.963607 | H22: =AVERAGE(F22:G22) -> 24.906975
A23: Investments | B23: =B4/IS!B2*365 -> 26.878474 | C23: =C4/IS!C2*365 -> 21.690325 | D23: =AVERAGE(B23:C23) -> 24.284399 | E23: =AVERAGE(C23:D23) -> 22.987362 | F23: =AVERAGE(D23:E23) -> 23.635881 | G23: =AVERAGE(E23:F23) -> 23.311621 | H23: =AVERAGE(F23:G23) -> 23.473751
A24: Trade Receivables | B24: =B5/IS!B2*365 -> 17.673275 | C24: =C5/IS!C2*365 -> 22.083538 | D24: =AVERAGE(B24:C24) -> 19.878406 | E24: =AVERAGE(C24:D24) -> 20.980972 | F24: =AVERAGE(D24:E24) -> 20.429689 | G24: =AVERAGE(E24:F24) -> 20.705331 | H24: =AVERAGE(F24:G24) -> 20.56751
A25: Bank balances other than cash equivalents | B25: =B6/IS!B2*365 -> 39.710321 | C25: =C6/IS!C2*365 -> 8.5755137 | D25: 22 | E25: 23 | F25: 24 | G25: 25 | H25: 26
A26: Loans | B26: =B7/IS!B2*365 -> 0.22408556 | C26: =C7/IS!C2*365 -> 0.26599705 | D26: =AVERAGE(B26:C26) -> 0.24504131 | E26: =AVERAGE(C26:D26) -> 0.25551918 | F26: =AVERAGE(D26:E26) -> 0.25028024 | G26: =AVERAGE(E26:F26) -> 0.25289971 | H26: =AVERAGE(F26:G26) -> 0.25158998
A27: Other financial assets (current) | B27: =B8/IS!B2*365 -> 8.4032086 | C27: =C8/IS!C2*365 -> 8.6044264 | D27: =AVERAGE(B27:C27) -> 8.5038175 | E27: =AVERAGE(C27:D27) -> 8.554122 | F27: =AVERAGE(D27:E27) -> 8.5289697 | G27: =AVERAGE(E27:F27) -> 8.5415459 | H27: =AVERAGE(F27:G27) -> 8.5352578
A28: Other current assets | B28: =B9/IS!B2*365 -> 4.2045528 | C28: =C9/IS!C2*365 -> 5.5223301 | D28: =AVERAGE(B28:C28) -> 4.8634415 | E28: =AVERAGE(C28:D28) -> 5.1928858 | F28: =AVERAGE(D28:E28) -> 5.0281636 | G28: =AVERAGE(E28:F28) -> 5.1105247 | H28: =AVERAGE(F28:G28) -> 5.0693442
A29: Assets held for sale | B29: =B10/IS!B2*365 -> 0.070763862 | C29: =C10/IS!C2*365 -> 0.13299853 | D29: =AVERAGE(B29:C29) -> 0.10188119 | E29: =AVERAGE(C29:D29) -> 0.11743986 | F29: =AVERAGE(D29:E29) -> 0.10966053 | G29: =AVERAGE(E29:F29) -> 0.11355019 | H29: =AVERAGE(F29:G29) -> 0.11160536
A31: Current Liabilities in days of sales:
A32: Trade payables - micro & small enterprises | B32: =B12/IS!B2*365 -> 1.4742471 | C32: =C12/IS!C2*365 -> 1.5208092 | D32: =AVERAGE(B32:C32) -> 1.4975282 | E32: =AVERAGE(C32:D32) -> 1.5091687 | F32: =AVERAGE(D32:E32) -> 1.5033484 | G32: =AVERAGE(E32:F32) -> 1.5062586 | H32: =AVERAGE(F32:G32) -> 1.5048035
A33: Trade payables - Others | B33: =B13/IS!B2*365 -> 60.361574 | C33: =C13/IS!C2*365 -> 63.908683 | D33: =AVERAGE(B33:C33) -> 62.135129 | E33: =AVERAGE(C33:D33) -> 63.021906 | F33: =AVERAGE(D33:E33) -> 62.578517 | G33: =AVERAGE(E33:F33) -> 62.800212 | H33: =AVERAGE(F33:G33) -> 62.689365
A34: Other financial liabilities | B34: =B14/IS!B2*365 -> 5.118586 | C34: =C14/IS!C2*365 -> 7.4016571 | D34: =AVERAGE(B34:C34) -> 6.2601216 | E34: =AVERAGE(C34:D34) -> 6.8308894 | F34: =AVERAGE(D34:E34) -> 6.5455055 | G34: =AVERAGE(E34:F34) -> 6.6881974 | H34: =AVERAGE(F34:G34) -> 6.6168514
A35: Other current liabilities | B35: =B15/IS!B2*365 -> 4.7588697 | C35: =C15/IS!C2*365 -> 5.5454603 | D35: =AVERAGE(B35:C35) -> 5.152165 | E35: =AVERAGE(C35:D35) -> 5.3488127 | F35: =AVERAGE(D35:E35) -> 5.2504888 | G35: =AVERAGE(E35:F35) -> 5.2996507 | H35: =AVERAGE(F35:G35) -> 5.2750698
A36: Provisions (current) | B36: =B16/IS!B2*365 -> 2.0049761 | C36: =C16/IS!C2*365 -> 3.9032176 | D36: =AVERAGE(B36:C36) -> 2.9540969 | E36: =AVERAGE(C36:D36) -> 3.4286572 | F36: =AVERAGE(D36:E36) -> 3.1913771 | G36: =AVERAGE(E36:F36) -> 3.3100171 | H36: =AVERAGE(F36:G36) -> 3.2506971
A37: Current Tax Liabilities | B37: =B17/IS!B2*365 -> 0 | C37: =C17/IS!C2*365 -> 11.004182 | D37: =0 -> 0 | E37: =AVERAGE(C37:D37) -> 5.5020912 | F37: =AVERAGE(D37:E37) -> 2.7510456 | G37: =AVERAGE(E37:F37) -> 4.1265684 | H37: =AVERAGE(F37:G37) -> 3.438807
A39: Other Long Term Items
A40: Deferred Income Taxes (Asset) | B40: =BS!B12 -> 10 | C40: =BS!C12 -> 17 | D40: =BS!D12 -> 17 | E40: =BS!E12 -> 17 | F40: =BS!F12 -> 17 | G40: =BS!G12 -> 17 | H40: =BS!H12 -> 17
A41: Other Long Term Items Assets | B41: =BS!B11 -> 760 | C41: =BS!C11 -> 763 | D41: =BS!D11 -> 763 | E41: =BS!E11 -> 763 | F41: =BS!F11 -> 763 | G41: =F41 -> 763 | H41: =G41 -> 763
A42: Total Other Assets | B42: =B40+B41 -> 770 | C42: =C40+C41 -> 780 | D42: =D40+D41 -> 780 | E42: =E40+E41 -> 780 | F42: =F40+F41 -> 780 | G42: =G40+G41 -> 780 | H42: =H40+H41 -> 780
A43: (Increase)/Decrease in Other Assets | C43: =B42-C42 -> -10 | D43: =C42-D42 -> 0 | E43: =D42-E42 -> 0 | F43: =E42-F42 -> 0
...

Sheet CAPEX Schedule 
A1: Capital Schedule | B1: 2024 | C1: =B1+1 -> 2025 | D1: 2026 | E1: =D1+1 -> 2027 | F1: =E1+1 -> 2028 | G1: =F1+1 -> 2029 | H1: =G1+1 -> 2030
A2: Property, Plant and Equipment | B2: =BS!B4 -> 8031 | C2: =BS!C4 -> 8625 | D2: =D3+D4 -> 7887.5505 | E2: =E3+E4 -> 7111.7964 | F2: =F3+F4 -> 6296.5389 | G2: =G3+G4 -> 5440.5417 | H2: =H3+H4 -> 4542.5299
A3: Owned | B3: 6517 | C3: 6941 | D3: =D18 -> 6342.642 | E3: =E18 -> 5713.2377 | F3: =F18 -> 5051.8156 | G3: =G18 -> 4357.3736 | H3: =H18 -> 3628.8785
A4: Leased (Right of Use Assets) | B4: 1514 | C4: 1684 | D4: =D19 -> 1544.9086 | E4: =E19 -> 1398.5587 | F4: =F19 -> 1244.7233 | G4: =G19 -> 1083.168 | H4: =H19 -> 913.65135
A5: Other Intangible Assets | B5: =BS!B7 -> 28247 | C5: =BS!C7 -> 28243 | D5: =D20 -> 29422.398 | E5: =E20 -> 30638.283 | F5: =F20 -> 31891.799 | G5: =G20 -> 33184.122 | H5: =H20 -> 34516.467
A7: Gross Long Term Assets: | B7: =SUM(B8:B10) -> 41985 | C7: =SUM(C8:C10) -> 43298 | D7: =C7+D25 -> 45153 | E7: =D7+E25 -> 47066.052 | F7: =E7+F25 -> 49038.972 | G7: =F7+G25 -> 51073.634 | H7: =G7+H25 -> 53171.971
A8: Owned | B8: 10999 | C8: 12004 | D8: =$C8/$C$7*D$7 -> 12518.283 | E8: =$C8/$C$7*E$7 -> 13048.66 | F8: =$C8/$C$7*F$7 -> 13595.635 | G8: =$C8/$C$7*G$7 -> 14159.728 | H8: =$C8/$C$7*H$7 -> 14741.474
A9: Leased (Right of Use Assets) | B9: 2580 | C9: 2878 | D9: =$C9/$C$7*D$7 -> 3001.3011 | E9: =$C9/$C$7*E$7 -> 3128.4608 | F9: =$C9/$C$7*F$7 -> 3259.6 | G9: =$C9/$C$7*G$7 -> 3394.8432 | H9: =$C9/$C$7*H$7 -> 3534.3187
A10: Other intangible assets (Goodwill) | B10: 28406 | C10: 28416 | D10: =$C10/$C$7*D$7 -> 29633.416 | E10: =$C10/$C$7*E$7 -> 30888.931 | F10: =$C10/$C$7*F$7 -> 32183.737 | G10: =$C10/$C$7*G$7 -> 33519.063 | H10: =$C10/$C$7*H$7 -> 34896.178
A12: Accumulated Depreciation: | B12: =SUM(B13:B15) -> 5504 | C12: =SUM(C13:C15) -> 6430 | D12: =C12+D22 -> 7843.0518 | E12: =D12+E22 -> 9315.972 | F12: =E12+F22 -> 10850.634 | G12: =F12+G22 -> 12448.971 | H12: =G12+H22 -> 14112.974
A13: Owned | B13: 4482 | C13: 5063 | D13: =$C13/$C$12*D$12 -> 6175.6409 | E13: =$C13/$C$12*E$12 -> 7335.4224 | F13: =$C13/$C$12*F$12 -> 8543.8198 | G13: =$C13/$C$12*G$12 -> 9802.3544 | H13: =$C13/$C$12*H$12 -> 11112.595
A14: Leased (Right of Use Assets) | B14: 863 | C14: 1194 | D14: =$C14/$C$12*D$12 -> 1456.3925 | E14: =$C14/$C$12*E$12 -> 1729.9021 | F14: =$C14/$C$12*F$12 -> 2014.8767 | G14: =$C14/$C$12*G$12 -> 2311.6751 | H14: =$C14/$C$12*H$12 -> 2620.6674
A15: Other intangible assets | B15: 159 | C15: 173 | D15: =$C15/$C$12*D$12 -> 211.01834 | E15: =$C15/$C$12*E$12 -> 250.64746 | F15: =$C15/$C$12*F$12 -> 291.93775 | G15: =$C15/$C$12*G$12 -> 334.9412 | H15: =$C15/$C$12*H$12 -> 379.71144
A17: Net Long Term Assets | B17: =SUM(B18:B20) -> 36481 | C17: =SUM(C18:C20) -> 36868 | D17: =D7-D12 -> 37309.948 | E17: =E7-E12 -> 37750.08 | F17: =F7-F12 -> 38188.338 | G17: =G7-G12 -> 38624.663 | H17: =H7-H12 -> 39058.997
A18: Owned | B18: =B8-B13 -> 6517 | C18: =C8-C13 -> 6941 | D18: =D8-D13 -> 6342.642 | E18: =E8-E13 -> 5713.2377 | F18: =F8-F13 -> 5051.8156 | G18: =G8-G13 -> 4357.3736 | H18: =H8-H13 -> 3628.8785
A19: Leased (Right of Use Assets) | B19: =B9-B14 -> 1717 | C19: =C9-C14 -> 1684 | D19: =D9-D14 -> 1544.9086 | E19: =E9-E14 -> 1398.5587 | F19: =F9-F14 -> 1244.7233 | G19: =G9-G14 -> 1083.168 | H19: =H9-H14 -> 913.65135
A20: Other intangible assets | B20: =B10-B15 -> 28247 | C20: =C10-C15 -> 28243 | D20: =D10-D15 -> 29422.398 | E20: =E10-E15 -> 30638.283 | F20: =F10-F15 -> 31891.799 | G20: =G10-G15 -> 33184.122 | H20: =H10-H15 -> 34516.467
A22: Depreciation and Amortization expenses | B22: =IS!B10 -> 1216 | C22: =IS!C10 -> 1355 | D22: =D7*D23 -> 1413.0518 | E22: =E7*E23 -> 1472.9202 | F22: =F7*F23 -> 1534.6623 | G22: =G7*G23 -> 1598.3365 | H22: =H7*H23 -> 1664.0034
A23: As a % of Opening GLTA | B23: =B22/B7 -> 0.028962725 | C23: =C22/C7 -> 0.031294748 | D23: =C23 -> 0.031294748 | E23: =D23 -> 0.031294748 | F23: =E23 -> 0.031294748 | G23: =F23 -> 0.031294748 | H23: =G23 -> 0.031294748
A25: Total CAPEX | C25: =SUM(C26:C27) -> 2529 | D25: =SUM(D26:D27) -> 1855 | E25: =SUM(E26:E27) -> 1913.0518 | F25: =SUM(F26:F27) -> 1972.9202 | G25: =SUM(G26:G27) -> 2034.6623 | H25: =SUM(H26:H27) -> 2098.3365
A26: Maintainance CAPEX | C26: =B22 -> 1216 | D26: =C22 -> 1355 | E26: =D22 -> 1413.0518 | F26: =E22 -> 1472.9202 | G26: =F22 -> 1534.6623 | H26: =G22 -> 1598.3365
A27: Growth CAPEX | C27: =C7-B7 -> 1313 | D27: =500 -> 500 | E27: =500 -> 500 | F27: =500 -> 500 | G27: =500 -> 500 | H27: =500 -> 500
A30: Beginning Accumulated Depreciation | C30: =B12 -> 5504 | D30: =C12 -> 6430 | E30: =D12 -> 7843.0518 | F30: =E12 -> 9315.972 | G30: =F12 -> 10850.634 | H30: =G12 -> 12448.971
A31: Total Depreciation Expense | C31: =C22 -> 1355 | D31: =D22 -> 1413.0518 | E31: =E22 -> 1472.9202 | F31: =F22 -> 1534.6623 | G31: =G22 -> 1598.3365 | H31: =H22 -> 1664.0034
A32: Ending Accumulated Depreciation | C32: =C12 -> 6430 | D32: =D12 -> 7843.0518 | E32: =E12 -> 9315.972 | F32: =F12 -> 10850.634 | G32: =G12 -> 12448.971 | H32: =H12 -> 14112.974
A33: Ending Gross PPE | C33: =C2 -> 8625 | D33: =D2 -> 7887.5505 | E33: =E2 -> 7111.7964 | F33: =F2 -> 6296.5389 | G33: =G2 -> 5440.5417 | H33: =H2 -> 4542.5299

Sheet FCFF
A1: Free Cashflow to Firm Calculator | B1: =E2027 -> 0 | C1: =E2028 -> 0 | D1: =E2029 -> 0 | E1: =E2030 -> 0 | F1: =E2031 -> 0
A2: EBIT | B2: =IS!D17+IS!D9 -> 15375.58 | C2: =IS!E17+IS!E9 -> 16415.087 | D2: =IS!F17+IS!F9 -> 17513.977 | E2: =IS!G17+IS!G9 -> 18818.244 | F2: =IS!H17+IS!H9 -> 20261.082
A3: EBIT(1-T) (or NOPAT) | B3: =B2*(1-B14) -> 11531.685 | C3: =C2*(1-C14) -> 12311.315 | D3: =D2*(1-D14) -> 13135.483 | E3: =E2*(1-E14) -> 14113.683 | F3: =F2*(1-F14) -> 15195.812
A4: Add Depreciation | B4: =IS!D10 -> 1413.0518 | C4: =IS!E10 -> 1472.9202 | D4: =IS!F10 -> 1534.6623 | E4: =IS!G10 -> 1598.3365 | F4: =IS!H10 -> 1664.0034
A5: Less Change in Net Working Capital FCFF | B5: =-'Working Cap Schedule '!D19 -> -4913.0043 | C5: =-'Working Cap Schedule '!E19 -> 800.03149 | D5: =-'Working Cap Schedule '!F19 -> -1260.8461 | E5: =-'Working Cap Schedule '!G19 -> -295.86784 | F5: =-'Working Cap Schedule '!H19 -> -998.53566
A6: Less Capital Expenditure | B6: =-'CAPEX Schedule '!D25 -> -1855 | C6: =-'CAPEX Schedule '!E25 -> -1913.0518 | D6: =-'CAPEX Schedule '!F25 -> -1972.9202 | E6: =-'CAPEX Schedule '!G25 -> -2034.6623 | F6: =-'CAPEX Schedule '!H25 -> -2098.3365
A7: FCFF | B7: =SUM(B3:B6) -> 6176.7328 | C7: =SUM(C3:C6) -> 12671.215 | D7: =SUM(D3:D6) -> 11436.379 | E7: =SUM(E3:E6) -> 13381.49 | F7: =SUM(F3:F6) -> 13762.943
A8: FCFF Growth | C8: =C7/B7-1 -> 1.0514429 | D8: =D7/C7-1 -> -0.097452083 | E8: =E7/D7-1 -> 0.17008103 | F8: =F7/E7-1 -> 0.028506036
A11: Valuation Parameters
A12: Valuation as on Specified Data | B12: =DATE(2026,2,28) -> 46081
A13: Date of Year Ending | B13: 46112
A14: Tax Rate (Effective Future Rate) | B14: 0.25 | C14: 0.25 | D14: 0.25 | E14: 0.25 | F14: 0.25
A15: WACC | B15: =WACC!J27 -> 0.12131208 | C15: =B15 -> 0.12131208 | D15: =C15 -> 0.12131208 | E15: =D15 -> 0.12131208 | F15: =E15 -> 0.12131208
A16: Terminal Growth Rate | B16: =WACC!J42 -> 0.038125
A18: Years
A19: Time to Cashflow in Years | B19: =($B$13-$B$12)/365 -> 0.084931507 | C19: =B19+1 -> 1.0849315 | D19: =C19+1 -> 2.0849315 | E19: =D19+1 -> 3.0849315 | F19: =E19+1 -> 4.0849315
A20: FCFF | B20: =B7 -> 6176.7328 | C20: =C7 -> 12671.215 | D20: =D7 -> 11436.379 | E20: =E7 -> 13381.49 | F20: =F7 -> 13762.943
A21: Discounted FCFF | B21: =B20/(1+$B$15)^B19 -> 6116.9576 | C21: =C20/(1+$B$15)^C19 -> 11190.987 | D21: =D20/(1+$B$15)^D19 -> 9007.6639 | E21: =E20/(1+$B$15)^E19 -> 9399.432 | F21: =F20/(1+$B$15)^F19 -> 8621.4825
A24: Terminal Value of FCFF | B24: =F20*(1+B16)/(B15-B16) -> 171753.29
A25: NPV of Explicit Cash Flows | B25: =SUM(B21:F21) -> 44336.523
A26: NPV of Terminal Value | B26: =B24/(1+B15)^F19 -> 107590.94
A27: Enterprise Value | B27: =B25+B26 -> 151927.46
A28: Less Debt | B28: ='Debt Schedule'!C3 -> 1
A29: Add Cash | B29: =BS!D19 -> 0
A30: No. of Shares Outstanding (in crores) | B30: =BS!D28 -> 235
A31: Equity Value | B31: =B27+B28-B29 -> 151928.46
A32: CMP | B32: =B31/B30 -> 646.50411
A33: Value per Share (today) | B33: 2340
A34: Upside/Downside | B34: =(B32-B33)/B33 -> -0.72371619
A37: Sensitivity Analysis
F38: WACC
B39: =B32 -> 646.50411 | C39: =D39-0.5% -> 0.10631208 | D39: =E39-0.5% -> 0.11131208 | E39: =F39-0.5% -> 0.11631208 | F39: =B15 -> 0.12131208 | G39: =F39+0.5% -> 0.12631208 | H39: =G39+0.5% -> 0.13131208 | I39: =H39+0.5% -> 0.13631208
B40: =B41-0.5% -> 0.023125 | C40: 671.00132 | D40: 760.51852 | E40: 815.13589 | F40: 815.13589 | G40: 760.51852 | H40: 671.00132 | I40: 570.95634
B41: =B42-0.5% -> 0.028125 | C41: 615.68258 | D41: 688.08179 | E41: 731.24083 | F41: 731.24083 | G41: 688.08179 | H41: 615.68258 | I41: 532.22961
B42: =B43-0.5% -> 0.033125 | C42: 592.24873 | D42: 658.02391 | E42: 696.85713 | F42: 696.85713 | G42: 658.02391 | H42: 592.24873 | I42: 515.43236
A43: Growth | B43: =B16 -> 0.038125 | C43: 592.24873 | D43: 658.02391 | E43: 696.85713 | F43: 696.85713 | G43: 658.02391 | H43: 592.24873 | I43: 515.43236
B44: =B43+0.5% -> 0.043125 | C44: 615.68258 | D44: 688.08179 | E44: 731.24083 | F44: 731.24083 | G44: 688.08179 | H44: 615.68258 | I44: 532.22961
B45: =B44+0.5% -> 0.048125 | C45: 671.00132 | D45: 760.51852 | E45: 815.13589 | F45: 815.13589 | G45: 760.51852 | H45: 671.00132 | I45: 570.95634
B46: =B45+0.5% -> 0.053125 | C46: 784.40239 | D46: 915.85713 | E46: 1000.1294 | F46: 1000.1294 | G46: 915.85713 | H46: 784.40239 | I46: 646.50411

Sheet FCFE
A1: Free Cashflow to Firm Calculator | B1: =E2027 -> 0 | C1: =E2028 -> 0 | D1: =E2029 -> 0 | E1: =E2030 -> 0 | F1: =E2031 -> 0
A2: EBIT- Interest -Tax | B2: =FCFF!B2-Assumption!D11-IS!D9 -> 18871.75 | C2: =FCFF!C2-FCFF!C14-IS!E9 -> 16016.537 | D2: =FCFF!D2-FCFF!D14-IS!F9 -> 17111.698 | E2: =FCFF!E2-FCFF!E14-IS!G9 -> 18412.236 | F2: =FCFF!F2-FCFF!F14-IS!H9 -> 19851.345
A3: Add Depreciation | B3: ='CAPEX Schedule '!D22 -> 1413.0518 | C3: ='CAPEX Schedule '!E22 -> 1472.9202 | D3: ='CAPEX Schedule '!F22 -> 1534.6623 | E3: ='CAPEX Schedule '!G22 -> 1598.3365 | F3: ='CAPEX Schedule '!H22 -> 1664.0034
A4: Less Change in Net Working Capital | B4: =-'Working Cap Schedule '!D19 -> -4913.0043 | C4: =-'Working Cap Schedule '!E19 -> 800.03149 | D4: =-'Working Cap Schedule '!F19 -> -1260.8461 | E4: =-'Working Cap Schedule '!G19 -> -295.86784 | F4: =-'Working Cap Schedule '!H19 -> -998.53566
A5: Less Capital Expenditure | B5: =-'CAPEX Schedule '!D25 -> -1855 | C5: =-'CAPEX Schedule '!E25 -> -1913.0518 | D5: =-'CAPEX Schedule '!F25 -> -1972.9202 | E5: =-'CAPEX Schedule '!G25 -> -2034.6623 | F5: =-'CAPEX Schedule '!H25 -> -2098.3365
A6: Add Net Borrowings | B6: ='Debt Schedule'!D21+'Debt Schedule'!D22 -> 49 | C6: ='Debt Schedule'!E21+'Debt Schedule'!E22 -> 50 | D6: ='Debt Schedule'!F21+'Debt Schedule'!F22 -> 50 | E6: ='Debt Schedule'!G21+'Debt Schedule'!G22 -> 50 | F6: ='Debt Schedule'!H21+'Debt Schedule'!H22 -> 50
A7: FCFE | B7: =SUM(B2:B6) -> 13565.797 | C7: =SUM(C2:C6) -> 16426.437 | D7: =SUM(D2:D6) -> 15462.594 | E7: =SUM(E2:E6) -> 17730.042 | F7: =SUM(F2:F6) -> 18468.476
A8: FCFF Growth | C8: =C7/B7-1 -> 0.21087149 | D8: =D7/C7-1 -> -0.058676325 | E8: =E7/D7-1 -> 0.1466409 | F8: =F7/E7-1 -> 0.041648713
A11: Valuation Parameters
A12: Valuation as on Specified Data | B12: =DATE(2026,2,28) -> 46081
A13: Date of Year Ending | B13: 46112
A14: Tax Rate (Effective Future Rate) | B14: 0.25
A15: WACC | B15: =WACC!J27 -> 0.12131208
A16: Terminal Growth Rate | B16: =WACC!J42 -> 0.038125
A18: Years
A19: Time to Cashflow in Years | B19: =($B$13-$B$12)/365 -> 0.084931507 | C19: =B19+1 -> 1.0849315 | D19: =C19+1 -> 2.0849315 | E19: =D19+1 -> 3.0849315 | F19: =E19+1 -> 4.0849315
A20: FCFE | B20: =B7 -> 13565.797 | C20: =C7 -> 16426.437 | D20: =D7 -> 15462.594 | E20: =E7 -> 17730.042 | F20: =F7 -> 18468.476
A21: Discounted FCFE | B21: =B20/(1+$B$15)^B19 -> 13434.514 | C21: =C20/(1+$B$15)^C19 -> 14507.531 | D21: =D20/(1+$B$15)^D19 -> 12178.842 | E21: =E20/(1+$B$15)^E19 -> 12453.944 | F21: =F20/(1+$B$15)^F19 -> 11569.157
A23: Terminal Value of FCFF | B23: =FCFF!B24 -> 171753.29
A24: NPV of Explicit Cash Flows | B24: =FCFF!B25 -> 44336.523
A25: NPV of Terminal Value | B25: =FCFF!B26 -> 107590.94
A26: Enterprise Value | B26: =FCFF!B27 -> 151927.46
A27: Less Debt | B27: =FCFF!B28 -> 1
A28: Add Cash | B28: =FCFF!B29 -> 0
A29: No. of Shares Outstanding (in crores) | B29: =FCFF!B30 -> 235
A30: Equity Value | B30: =FCFF!B31 -> 151928.46
A31: CMP | B31: =FCFF!B32 -> 646.50411
A32: Value per Share (today) | B32: =FCFF!B33 -> 2340
A33: Upside/Downside | B33: =FCFF!B34 -> -0.72371619

Sheet WACC
A1: Date | B1: HINDUNILVR.NS | C1: ^NSEI
A2: 44256 | B2: 2236.0205 | C2: 14690.7 | F2: Returns Nifty | G2: Returns HUL
A3: 44287 | B3: 2164.5212 | C3: 14631.1 | F3: =LN(C3/C2) -> -0.0040652803 | G3: =LN(B3/B2) -> -0.032498526
A4: 44317 | B4: 2151.9226 | C4: 15582.8 | F4: =LN(C4/C3) -> 0.063018356 | G4: =LN(B4/B3) -> -0.0058375223
A5: 44348 | B5: 2272.6208 | C5: 15721.5 | F5: =LN(C5/C4) -> 0.0088614729 | G5: =LN(B5/B4) -> 0.054572046
A6: 44378 | B6: 2161.2407 | C6: 15763.05 | F6: =LN(C6/C5) -> 0.0026393789 | G6: =LN(B6/B5) -> -0.050251259
A7: 44409 | B7: 2523.2234 | C7: 17132.199 | F7: =LN(C7/C6) -> 0.083291107 | G7: =LN(B7/B6) -> 0.15485474
A8: 44440 | B8: 2502.5676 | C8: 17618.15 | F8: =LN(C8/C7) -> 0.027969955 | G8: =LN(B8/B7) -> -0.008219951
A9: 44470 | B9: 2216.6772 | C9: 17671.65 | F9: =LN(C9/C8) -> 0.0030320398 | G9: =LN(B9/B8) -> -0.12130792
A10: 44501 | B10: 2159.8442 | C10: 16983.199 | F10: =LN(C10/C9) -> -0.039737109 | G10: =LN(B10/B9) -> -0.025973231
A11: 44531 | B11: 2199.5454 | C11: 17354.051 | F11: =LN(C11/C10) -> 0.021601379 | G11: =LN(B11/B10) -> 0.0182146
A12: 44562 | B12: 2119.0247 | C12: 17339.85 | F12: =LN(C12/C11) -> -0.0008186553 | G12: =LN(B12/B11) -> -0.037294791
A13: 44593 | B13: 2024.2922 | C13: 16793.9 | F13: =LN(C13/C12) -> -0.03199155 | G13: =LN(B13/B12) -> -0.045735789
A14: 44621 | B14: 1909.2426 | C14: 17464.75 | F14: =LN(C14/C13) -> 0.039168815 | G14: =LN(B14/B13) -> -0.058513532
... A20: 44805 | B20: 2535.1477 | C20: 17094.35 | F20: =LN(C20/C19) -> -0.03816139 | G20: =LN(B20/B19) -> 0.013666194
A21: 44835 | B21: 2398.1165 | C21: 18012.199 | F21: =LN(C21/C20) -> 0.052301286 | G21: =LN(B21/B20) -> -0.055568283 | I21: Slope / Beta | J21: =SLOPE(G3:G61,F3:F61) -> 0.77138602
A22: 44866 | B22: 2523.7717 | C22: 18758.35 | F22: =LN(C22/C21) -> 0.040589703 | G22: =LN(B22/B21) -> 0.051070881 | I22: Total Capital | J22: =BS!C28+BS!C29+BS!C30+BS!C33 -> 50852
A23: 44896 | B23: 2424.0029 | C23: 18105.301 | F23: =LN(C23/C22) -> -0.03543421 | G23: =LN(B23/B22) -> -0.040334223 | I23: Weight of Debt | J23: =BS!C33/WACC!J22 -> 0.024443483
A24: 44927 | B24: 2438.8628 | C24: 17662.15 | F24: =LN(C24/C23) -> -0.024780802 | G24: =LN(B24/B23) -> 0.0061115854 | I24: Weight of Equity | J24: =1-J23 -> 0.97555652
A25: 44958 | B25: 2328.9753 | C25: 17303.949 | F25: =LN(C25/C24) -> -0.0204892 | G25: =LN(B25/B24) -> -0.046103459 | I25: Cost of Debt | J25: ='Debt Schedule'!C19 -> 0.077109897
A26: 44986 | B26: 2423.3406 | C26: 17359.75 | F26: =LN(C26/C25) -> 0.0032195542 | G26: =LN(B26/B25) -> 0.039718588 | I26: Cost of Equity | J26: =J30+J31*J32 -> 0.12290263
A27: 45017 | B27: 2325.8047 | C27: 18065 | F27: =LN(C27/C26) -> 0.039822056 | G27: =LN(B27/B26) -> -0.04108091 | I27: WACC | J27: =(J23*J25*(1-FCFF!B14)+(WACC!J24*WACC!J26)) -> 0.12131208
A28: 45047 | B28: 2524.804 | C28: 18534.4 | F28: =LN(C28/C27) -> 0.025652121 | G28: =LN(B28/B27) -> 0.082097337 | I28: Cost of Equity | J28: Ke = Rf + Beta * ERP
A29: 45078 | B29: 2534.8367 | C29: 19189.051 | F29: =LN(C29/C28) -> 0.034711359 | G29: =LN(B29/B28) -> 0.0039657868
A30: 45108 | B30: 2443.5623 | C30: 19753.801 | F30: =LN(C30/C29) -> 0.029006073 | G30: =LN(B30/B29) -> -0.036672289 | I30: RF | J30: 0.0669
A31: 45139 | B31: 2390.3645 | C31: 19253.801 | F31: =LN(C31/C30) -> -0.025637433 | G31: =LN(B31/B30) -> -0.02201105 | I31: BETA | J31: =J21 -> 0.77138602
A32: 45170 | B32: 2352.7207 | C32: 19638.301 | F32: =LN(C32/C31) -> 0.019773296 | G32: =LN(B32/B31) -> -0.015873461 | I32: ERF | J32: 0.0726
A33: 45200 | B33: 2370.2781 | C33: 19079.6 | F33: =LN(C33/C32) -> -0.0288621 | G33: =LN(B33/B32) -> 0.0074348755
A34: 45231 | B34: 2429.0103 | C34: 20133.15 | F34: =LN(C34/C33) -> 0.053748049 | G34: =LN(B34/B33) -> 0.024476591
A35: 45261 | B35: 2560.6331 | C35: 21731.4 | F35: =LN(C35/C34) -> 0.076390508 | G35: =LN(B35/B34) -> 0.052770644 | I35: Terminal Growth Rate
A36: 45292 | B36: 2385.3074 | C36: 21725.699 | F36: =LN(C36/C35) -> -0.00026238161 | G36: =LN(B36/B35) -> -0.070926522 | K36: Weights
A37: 45323 | B37: 2318.7429 | C37: 21982.801 | F37: =LN(C37/C36) -> 0.011764509 | G37: =LN(B37/B36) -> -0.0283028 | I37: GDP | J37: 0.065 | K37: 0.25
A38: 45352 | B38: 2176.5312 | C38: 22326.9 | F38: =LN(C38/C37) -> 0.015531882 | G38: =LN(B38/B37) -> -0.063292754 | I38: CPI Inflation | J38: 0.0275 | K38: 0.25
A39: 45383 | B39: 2143.9458 | C39: 22604.85 | F39: =LN(C39/C38) -> 0.012372221 | G39: =LN(B39/B38) -> -0.015084476 | I39: FMCG Industry | J39: 0.05 | K39: 0.25
A40: 45413 | B40: 2238.7219 | C40: 22530.699 | F40: =LN(C40/C39) -> -0.0032856788 | G40: =LN(B40/B39) -> 0.04325717 | I40: Population Growth | J40: 0.01 | K40: 0.25
A41: 45444 | B41: 2377.137 | C41: 24010.6 | F41: =LN(C41/C40) -> 0.063616594 | G41: =LN(B41/B40) -> 0.059991673
A42: 45474 | B42: 2626.0537 | C42: 24951.15 | F42: =LN(C42/C41) -> 0.038424546 | G42: =LN(B42/B41) -> 0.099585422 | I42: Growth Rate | J42: =SUMPRODUCT(J37:J40,K37:K40) -> 0.038125
A43: 45505 | B43: 2696.2754 | C43: 25235.9 | F43: =LN(C43/C42) -> 0.01134767 | G43: =LN(B43/B42) -> 0.026389107
A44: 45536 | B44: 2871.2712 | C44: 25810.85 | F44: =LN(C44/C43) -> 0.022527332 | G44: =LN(B44/B43) -> 0.062883537 | I44: Current Market Price (as on 27-02-26) | J44: =2340 -> 2340
A45: 45566 | B45: 2453.8726 | C45: 24205.35 | F45: =LN(C45/C44) -> -0.064221264 | G45: =LN(B45/B44) -> -0.15708746
...
